<?xml version="1.0" encoding="utf-8"?>
<!-- =================================================================================== -->
<!-- |    This document was autogenerated by xacro from sharework_cembre_simplified.xacro | -->
<!-- |    EDITING THIS FILE BY HAND IS NOT RECOMMENDED                                 | -->
<!-- =================================================================================== -->
<robot name="sharework_simplified">
  <material name="aluminum">
    <color rgba="0.5 0.5 0.5 1"/>
  </material>
  <material name="plastic">
    <color rgba="0.1 0.1 0.1 1"/>
  </material>
  <link name="world"/>
  <joint name="base_to_right_leg" type="fixed">
    <parent link="world"/>
    <child link="portal"/>
    <origin xyz="0 0 0"/>
  </joint>
  <!-- PORTAL -->
  <link name="portal"/>
  <joint name="portal_to_right_column" type="fixed">
    <parent link="world"/>
    <child link="right_column"/>
    <origin xyz="-0.58 1.0 0"/>
  </joint>
  <joint name="portal_to_left_column" type="fixed">
    <parent link="world"/>
    <child link="left_column"/>
    <origin xyz="-0.58 -1.0 0"/>
  </joint>
  <link name="right_column">
    <visual>
      <origin rpy="0 0 0" xyz="0.29 0.06 1.5"/>
      <geometry>
        <box size="0.58 0.12 3.0"/>
      </geometry>
      <material name="Grey">
        <color rgba="0.517647058823529 0.529411764705882 0.537254901960784 1"/>
      </material>
    </visual>
    <collision>
      <origin rpy="0 0 0" xyz="0.29 0.06 1.5"/>
      <geometry>
        <box size="0.66 0.2 3.0"/>
      </geometry>
      <material name="Grey">
        <color rgba="0.517647058823529 0.529411764705882 0.537254901960784 1"/>
      </material>
    </collision>
  </link>
  <link name="left_column">
    <visual>
      <origin rpy="0 0 0" xyz="0.29 -0.06 1.5"/>
      <geometry>
        <box size="0.58 0.12 3.0"/>
      </geometry>
      <material name="Grey">
        <color rgba="0.517647058823529 0.529411764705882 0.537254901960784 1"/>
      </material>
    </visual>
    <collision>
      <origin rpy="0 0 0" xyz="0.29 -0.06 1.5"/>
      <geometry>
        <box size="0.66 0.2 3.0"/>
      </geometry>
      <material name="Grey">
        <color rgba="0.517647058823529 0.529411764705882 0.537254901960784 1"/>
      </material>
    </collision>
  </link>
  <joint name="portal_to_lower_beam" type="fixed">
    <parent link="world"/>
    <child link="lower_beam"/>
    <origin xyz="-0.58 0 0.895"/>
  </joint>
  <link name="lower_beam">
    <visual>
      <origin rpy="0 0 0" xyz="0.29 0 -0.06"/>
      <geometry>
        <box size="0.58 2.0 0.2"/>
      </geometry>
      <material name="Grey">
        <color rgba="0.517647058823529 0.529411764705882 0.537254901960784 1"/>
      </material>
    </visual>
    <collision>
      <origin rpy="0 0 0" xyz="0.29 0 -0.06"/>
      <geometry>
        <box size="0.58 2.0 0.12"/>
      </geometry>
      <material name="Grey">
        <color rgba="0.517647058823529 0.529411764705882 0.537254901960784 1"/>
      </material>
    </collision>
  </link>
  <joint name="portal_to_upper_beam" type="fixed">
    <parent link="world"/>
    <child link="upper_beam"/>
    <origin xyz="-0.58 0 2.208"/>
  </joint>
  <link name="upper_beam">
    <visual>
      <origin rpy="0 0 0" xyz="0.29 0 0.06"/>
      <geometry>
        <box size="0.58 2.0 0.12"/>
      </geometry>
      <material name="Grey">
        <color rgba="0.517647058823529 0.529411764705882 0.537254901960784 1"/>
      </material>
    </visual>
    <collision>
      <origin rpy="0 0 0" xyz="0.29 0 0.06"/>
      <geometry>
        <box size="0.58 2.0 0.12"/>
      </geometry>
      <material name="Grey">
        <color rgba="0.517647058823529 0.529411764705882 0.537254901960784 1"/>
      </material>
    </collision>
  </link>
  <!-- guide -->
  <joint name="upper_beam_guide" type="fixed">
    <parent link="upper_beam"/>
    <child link="guide_fixed"/>
    <origin xyz="0.325 -1.0 -0.14"/>
  </joint>
  <link name="guide_fixed">
    <visual>
      <origin rpy="0 0 0" xyz="0 1.0 0.07"/>
      <geometry>
        <box size="0.28 2.0 0.14"/>
      </geometry>
      <material name="Grey">
        <color rgba="0.517647058823529 0.529411764705882 0.537254901960784 1"/>
      </material>
    </visual>
    <collision>
      <origin rpy="0 0 0" xyz="0 1.0 0.07"/>
      <geometry>
        <box size="0.58 2.0 0.14"/>
      </geometry>
      <material name="Grey">
        <color rgba="0.517647058823529 0.529411764705882 0.537254901960784 1"/>
      </material>
    </collision>
  </link>
  <joint name="track_joint" type="fixed">
    <parent link="guide_fixed"/>
    <child link="cursor"/>
    <origin xyz="0 1.061 -0.01"/>
    <limit effort="1000.0" lower="0" upper="1.4" velocity="0.5"/>
    <axis xyz="0 1 0"/>
  </joint>
  <link name="cursor">
    <visual>
      <origin rpy="0 0 0" xyz="0 0 0.005"/>
      <geometry>
        <box size="0.28 0.28 0.01"/>
      </geometry>
      <material name="DarkGrey">
        <color rgba="0.1 0.1 0.1 1"/>
      </material>
    </visual>
    <collision>
      <origin rpy="0 0 0" xyz="0 0 0.005"/>
      <geometry>
        <box size="0.28 0.28 0.01"/>
      </geometry>
      <material name="DarkGrey">
        <color rgba="0.1 0.1 0.1 1"/>
      </material>
    </collision>
  </link>
  <!-- TABLE -->
  <joint name="portal_to_table" type="fixed">
    <parent link="world"/>
    <child link="table"/>
    <origin xyz="0 -1.0 0.895"/>
  </joint>
  <link name="table">
    <visual>
      <origin rpy="0 0 0" xyz="0.3 1.0 -0.02"/>
      <geometry>
        <box size="0.6 2.0 0.04"/>
      </geometry>
      <material name="Beech">
        <color rgba="0.952941176470588 0.694117647058823 0.392156862745098 1"/>
      </material>
    </visual>
    <collision>
      <origin rpy="0 0 0" xyz="0.3 1.0 -0.02"/>
      <geometry>
        <box size="0.6 2.0 0.04"/>
      </geometry>
      <material name="Beech">
        <color rgba="0.952941176470588 0.694117647058823 0.392156862745098 1"/>
      </material>
    </collision>
  </link>
  <joint name="table_to_rail" type="fixed">
    <parent link="table"/>
    <child link="rail"/>
    <origin xyz="0.342 -0.612 0.17"/>
  </joint>
  <link name="rail">
    <visual>
      <origin rpy="0 0 0" xyz="0 1.612 -0.085"/>
      <geometry>
        <box size="0.36 3.224 0.17"/>
      </geometry>
      <material name="Grey">
        <color rgba="0.517647058823529 0.529411764705882 0.537254901960784 1"/>
      </material>
    </visual>
    <collision>
      <origin rpy="0 0 0" xyz="0 1.612 -0.085"/>
      <geometry>
        <box size="0.36 3.224 0.17"/>
      </geometry>
      <material name="Grey">
        <color rgba="0.517647058823529 0.529411764705882 0.537254901960784 1"/>
      </material>
    </collision>
  </link>
  <!--
  Author: Kelsey Hawkins
  Contributers: Jimmy Da Silva, Ajit Krisshna N L, Muhammad Asif Rana
-->
  <link name="base_link">
    <visual>
      <geometry>
        <mesh filename="/mesh/ur_e_description/meshes/ur10e/visual/base.dae"/>
      </geometry>
      <material name="LightGrey">
        <color rgba="0.7 0.7 0.7 1.0"/>
      </material>
    </visual>
    <collision>
      <geometry>
        <mesh filename="/mesh/ur_e_description/meshes/ur10e/collision/base.stl"/>
      </geometry>
    </collision>
    <inertial>
      <mass value="4.0"/>
      <origin rpy="0 0 0" xyz="0.0 0.0 0.0"/>
      <inertia ixx="0.0061063308908" ixy="0.0" ixz="0.0" iyy="0.0061063308908" iyz="0.0" izz="0.01125"/>
    </inertial>
  </link>
  <joint name="shoulder_pan_joint" type="revolute">
    <parent link="base_link"/>
    <child link="shoulder_link"/>
    <origin rpy="0.0 0.0 0.0" xyz="0.0 0.0 0.181"/>
    <axis xyz="0 0 1"/>
    <limit effort="330.0" lower="-3.14159265359" upper="3.14159265359" velocity="3.14"/>
    <dynamics damping="0.0" friction="0.0"/>
  </joint>
  <link name="shoulder_link">
    <visual>
      <geometry>
        <mesh filename="/mesh/ur_e_description/meshes/ur10e/visual/shoulder.dae"/>
      </geometry>
      <material name="LightGrey">
        <color rgba="0.7 0.7 0.7 1.0"/>
      </material>
    </visual>
    <collision>
      <geometry>
        <mesh filename="/mesh/ur_e_description/meshes/ur10e/collision/shoulder.stl"/>
      </geometry>
    </collision>
    <inertial>
      <mass value="7.778"/>
      <origin rpy="0 0 0" xyz="0.0 0.0 0.0"/>
      <inertia ixx="0.0314743125769" ixy="0.0" ixz="0.0" iyy="0.0314743125769" iyz="0.0" izz="0.021875625"/>
    </inertial>
  </link>
  <joint name="shoulder_lift_joint" type="revolute">
    <parent link="shoulder_link"/>
    <child link="upper_arm_link"/>
    <origin rpy="0.0 1.57079632679 0.0" xyz="0.0 0.176 0.0"/>
    <axis xyz="0 1 0"/>
    <limit effort="330.0" lower="-3.14159265359" upper="0.052359878" velocity="3.14"/>
    <dynamics damping="0.0" friction="0.0"/>
  </joint>
  <link name="upper_arm_link">
    <visual>
      <geometry>
        <mesh filename="/mesh/ur_e_description/meshes/ur10e/visual/upperarm.dae"/>
      </geometry>
      <material name="LightGrey">
        <color rgba="0.7 0.7 0.7 1.0"/>
      </material>
    </visual>
    <collision>
      <geometry>
        <mesh filename="/mesh/ur_e_description/meshes/ur10e/collision/upperarm.stl"/>
      </geometry>
    </collision>
    <inertial>
      <mass value="12.93"/>
      <origin rpy="0 0 0" xyz="0.0 0.0 0.3065"/>
      <inertia ixx="0.42307374077" ixy="0.0" ixz="0.0" iyy="0.42307374077" iyz="0.0" izz="0.036365625"/>
    </inertial>
  </link>
  <joint name="elbow_joint" type="revolute">
    <parent link="upper_arm_link"/>
    <child link="forearm_link"/>
    <origin rpy="0.0 0.0 0.0" xyz="0.0 -0.137 0.613"/>
    <axis xyz="0 1 0"/>
    <limit effort="150.0" lower="-3.14159265359" upper="3.14159265359" velocity="3.14"/>
    <dynamics damping="0.0" friction="0.0"/>
  </joint>
  <link name="forearm_link">
    <visual>
      <geometry>
        <mesh filename="/mesh/ur_e_description/meshes/ur10e/visual/forearm.dae"/>
      </geometry>
      <material name="LightGrey">
        <color rgba="0.7 0.7 0.7 1.0"/>
      </material>
    </visual>
    <collision>
      <geometry>
        <mesh filename="/mesh/ur_e_description/meshes/ur10e/collision/forearm.stl"/>
      </geometry>
    </collision>
    <inertial>
      <mass value="3.87"/>
      <origin rpy="0 0 0" xyz="0.0 0.0 0.2855"/>
      <inertia ixx="0.110590365764" ixy="0.0" ixz="0.0" iyy="0.110590365764" iyz="0.0" izz="0.010884375"/>
    </inertial>
  </link>
  <joint name="wrist_1_joint" type="revolute">
    <parent link="forearm_link"/>
    <child link="wrist_1_link"/>
    <origin rpy="0.0 1.57079632679 0.0" xyz="0.0 0.0 0.571"/>
    <axis xyz="0 1 0"/>
    <limit effort="54.0" lower="-3.14159265359" upper="3.14159265359" velocity="6.28"/>
    <dynamics damping="0.0" friction="0.0"/>
  </joint>
  <link name="wrist_1_link">
    <visual>
      <geometry>
        <mesh filename="/mesh/ur_e_description/meshes/ur10e/visual/wrist1.dae"/>
      </geometry>
      <material name="LightGrey">
        <color rgba="0.7 0.7 0.7 1.0"/>
      </material>
    </visual>
    <collision>
      <geometry>
        <mesh filename="/mesh/ur_e_description/meshes/ur10e/collision/wrist1.stl"/>
      </geometry>
    </collision>
    <inertial>
      <mass value="1.96"/>
      <origin rpy="0 0 0" xyz="0.0 0.135 0.0"/>
      <inertia ixx="0.0051082479567" ixy="0.0" ixz="0.0" iyy="0.0051082479567" iyz="0.0" izz="0.0055125"/>
    </inertial>
  </link>
  <joint name="wrist_2_joint" type="revolute">
    <parent link="wrist_1_link"/>
    <child link="wrist_2_link"/>
    <origin rpy="0.0 0.0 0.0" xyz="0.0 0.135 0.0"/>
    <axis xyz="0 0 1"/>
    <limit effort="54.0" lower="-3.14159265359" upper="3.14159265359" velocity="6.28"/>
    <dynamics damping="0.0" friction="0.0"/>
  </joint>
  <link name="wrist_2_link">
    <visual>
      <geometry>
        <mesh filename="/mesh/ur_e_description/meshes/ur10e/visual/wrist2.dae"/>
      </geometry>
      <material name="LightGrey">
        <color rgba="0.7 0.7 0.7 1.0"/>
      </material>
    </visual>
    <collision>
      <geometry>
        <mesh filename="/mesh/ur_e_description/meshes/ur10e/collision/wrist2.stl"/>
      </geometry>
    </collision>
    <inertial>
      <mass value="1.96"/>
      <origin rpy="0 0 0" xyz="0.0 0.0 0.12"/>
      <inertia ixx="0.0051082479567" ixy="0.0" ixz="0.0" iyy="0.0051082479567" iyz="0.0" izz="0.0055125"/>
    </inertial>
  </link>
  <joint name="wrist_3_joint" type="revolute">
    <parent link="wrist_2_link"/>
    <child link="wrist_3_link"/>
    <origin rpy="0.0 0.0 0.0" xyz="0.0 0.0 0.12"/>
    <axis xyz="0 1 0"/>
    <limit effort="54.0" lower="-6.28318530718" upper="6.28318530718" velocity="6.28"/>
    <dynamics damping="0.0" friction="0.0"/>
  </joint>
  <link name="wrist_3_link">
    <visual>
      <geometry>
        <mesh filename="/mesh/ur_e_description/meshes/ur10e/visual/wrist3.dae"/>
      </geometry>
      <material name="LightGrey">
        <color rgba="0.7 0.7 0.7 1.0"/>
      </material>
    </visual>
    <collision>
      <geometry>
        <mesh filename="/mesh/ur_e_description/meshes/ur10e/collision/wrist3.stl"/>
      </geometry>
    </collision>
    <inertial>
      <mass value="0.202"/>
      <origin rpy="1.57079632679 0 0" xyz="0.0 0.092 0.0"/>
      <inertia ixx="0.000144345775595" ixy="0.0" ixz="0.0" iyy="0.000144345775595" iyz="0.0" izz="0.000204525"/>
    </inertial>
  </link>
  <joint name="ee_fixed_joint" type="fixed">
    <parent link="wrist_3_link"/>
    <child link="ee_link"/>
    <origin rpy="0.0 0.0 1.57079632679" xyz="0.0 0.117 0.0"/>
  </joint>
  <link name="ee_link">
    <collision>
      <geometry>
        <box size="0.01 0.01 0.01"/>
      </geometry>
      <origin rpy="0 0 0" xyz="-0.01 0 0"/>
    </collision>
  </link>
  <transmission name="shoulder_pan_trans">
    <type>transmission_interface/SimpleTransmission</type>
    <joint name="shoulder_pan_joint">
      <hardwareInterface>hardware_interface/PositionJointInterface</hardwareInterface>
    </joint>
    <actuator name="shoulder_pan_motor">
      <mechanicalReduction>1</mechanicalReduction>
    </actuator>
  </transmission>
  <transmission name="shoulder_lift_trans">
    <type>transmission_interface/SimpleTransmission</type>
    <joint name="shoulder_lift_joint">
      <hardwareInterface>hardware_interface/PositionJointInterface</hardwareInterface>
    </joint>
    <actuator name="shoulder_lift_motor">
      <mechanicalReduction>1</mechanicalReduction>
    </actuator>
  </transmission>
  <transmission name="elbow_trans">
    <type>transmission_interface/SimpleTransmission</type>
    <joint name="elbow_joint">
      <hardwareInterface>hardware_interface/PositionJointInterface</hardwareInterface>
    </joint>
    <actuator name="elbow_motor">
      <mechanicalReduction>1</mechanicalReduction>
    </actuator>
  </transmission>
  <transmission name="wrist_1_trans">
    <type>transmission_interface/SimpleTransmission</type>
    <joint name="wrist_1_joint">
      <hardwareInterface>hardware_interface/PositionJointInterface</hardwareInterface>
    </joint>
    <actuator name="wrist_1_motor">
      <mechanicalReduction>1</mechanicalReduction>
    </actuator>
  </transmission>
  <transmission name="wrist_2_trans">
    <type>transmission_interface/SimpleTransmission</type>
    <joint name="wrist_2_joint">
      <hardwareInterface>hardware_interface/PositionJointInterface</hardwareInterface>
    </joint>
    <actuator name="wrist_2_motor">
      <mechanicalReduction>1</mechanicalReduction>
    </actuator>
  </transmission>
  <transmission name="wrist_3_trans">
    <type>transmission_interface/SimpleTransmission</type>
    <joint name="wrist_3_joint">
      <hardwareInterface>hardware_interface/PositionJointInterface</hardwareInterface>
    </joint>
    <actuator name="wrist_3_motor">
      <mechanicalReduction>1</mechanicalReduction>
    </actuator>
  </transmission>
  <gazebo reference="shoulder_link">
    <selfCollide>true</selfCollide>
  </gazebo>
  <gazebo reference="upper_arm_link">
    <selfCollide>true</selfCollide>
  </gazebo>
  <gazebo reference="forearm_link">
    <selfCollide>true</selfCollide>
  </gazebo>
  <gazebo reference="wrist_1_link">
    <selfCollide>true</selfCollide>
  </gazebo>
  <gazebo reference="wrist_3_link">
    <selfCollide>true</selfCollide>
  </gazebo>
  <gazebo reference="wrist_2_link">
    <selfCollide>true</selfCollide>
  </gazebo>
  <gazebo reference="ee_link">
    <selfCollide>true</selfCollide>
  </gazebo>
  <!-- ROS base_link to UR 'Base' Coordinates transform -->
  <link name="base"/>
  <joint name="base_link-base_fixed_joint" type="fixed">
    <!-- NOTE: this rotation is only needed as long as base_link itself is
                 not corrected wrt the real robot (ie: rotated over 180
                 degrees)
      -->
    <origin rpy="0 0 -3.14159265359" xyz="0 0 0"/>
    <parent link="base_link"/>
    <child link="base"/>
  </joint>
  <!-- Frame coincident with all-zeros TCP on UR controller -->
  <link name="tool0"/>
  <joint name="wrist_3_link-tool0_fixed_joint" type="fixed">
    <origin rpy="-1.57079632679 0 0" xyz="0 0.117 0"/>
    <parent link="wrist_3_link"/>
    <child link="tool0"/>
  </joint>
  <joint name="cursor_to_base" type="fixed">
    <parent link="cursor"/>
    <child link="base_link"/>
    <origin rpy="3.14159265359 0.0 1.57079632679" xyz="0.0 0.0 0.0"/>
  </joint>
  <!-- walls  -->
  <joint name="portal_to_wall" type="fixed">
    <parent link="portal"/>
    <child link="wall"/>
    <origin xyz="-1.08 0 0"/>
  </joint>
  <link name="wall">
    <visual>
      <origin rpy="0 0 0" xyz="-0.05 0 1.5"/>
      <geometry>
        <box size="0.1 4.24 3.0"/>
      </geometry>
      <material name="White">
        <color rgba="1 1 1 1"/>
      </material>
    </visual>
    <collision>
      <origin rpy="0 0 0" xyz="-0.05 0 1.5"/>
      <geometry>
        <box size="0.1 4.24 3.0"/>
      </geometry>
      <material name="White">
        <color rgba="1 1 1 1"/>
      </material>
    </collision>
  </link>
  <joint name="wall_to_ec" type="fixed">
    <parent link="wall"/>
    <child link="ec"/>
    <origin xyz="0 0.3 0"/>
  </joint>
  <link name="ec">
    <visual>
      <origin rpy="0 0 0" xyz="0.2 0.35 1.0"/>
      <geometry>
        <box size="0.4 0.7 2.0"/>
      </geometry>
      <material name="White">
        <color rgba="1 1 1 1"/>
      </material>
    </visual>
    <collision>
      <origin rpy="0 0 0" xyz="0.2 0.35 1.0"/>
      <geometry>
        <box size="0.4 0.7 2.0"/>
      </geometry>
      <material name="White">
        <color rgba="1 1 1 1"/>
      </material>
    </collision>
  </link>
  <joint name="portal_to_floor" type="fixed">
    <parent link="portal"/>
    <child link="floor"/>
    <origin xyz="-1.08 0 0"/>
  </joint>
  <link name="floor">
    <visual>
      <origin rpy="0 0 0" xyz="1.92 0 -0.005"/>
      <geometry>
        <box size="6 6 0.01"/>
      </geometry>
      <material name="White">
        <color rgba="1 1 1 1"/>
      </material>
    </visual>
  </link>
  <!-- Screw driver -->
  <joint name="table_to_screwdriver_holder" type="fixed">
    <parent link="table"/>
    <child link="screwdriver_holder"/>
    <origin xyz="0.2 -0.05 1.5"/>
  </joint>
  <link name="screwdriver_holder">
    <visual>
      <origin rpy="0 0 0" xyz="0 0 0"/>
      <geometry>
        <box size="0.4 0.2 1.5"/>
      </geometry>
      <material name="White">
        <color rgba="1 1 1 1"/>
      </material>
    </visual>
    <collision>
      <origin rpy="0 0 0" xyz="0 0 0"/>
      <geometry>
        <box size="0.2 0.2 2"/>
      </geometry>
      <material name="White">
        <color rgba="1 1 1 1"/>
      </material>
    </collision>
  </link>
  <!-- Virtual Wall -->
  <joint name="virtual_wall_1_joint" type="fixed">
    <parent link="guide_fixed"/>
    <child link="virtual_wall_1"/>
    <origin xyz="0 0 0.0"/>
  </joint>
  <link name="virtual_wall_1">
    <collision>
      <origin rpy="0 0 0" xyz="-0.5 1.0 0.0005"/>
      <geometry>
        <box size="1.58 2.24 0.001"/>
      </geometry>
      <material name="VirtualWallColor">
        <color rgba="0.1 0.1 0.1 0.1"/>
      </material>
    </collision>
  </link>
  <joint name="virtual_wall_2_joint" type="fixed">
    <parent link="world"/>
    <child link="virtual_wall_2"/>
    <origin xyz="1.7 0 0.0"/>
  </joint>
  <link name="virtual_wall_2">
    <collision>
      <origin rpy="0 0 0" xyz="0.0005 0 1"/>
      <geometry>
        <box size="0.001 2.24 2"/>
      </geometry>
      <material name="VirtualWallColor2">
        <color rgba="0.1 0.1 0.1 0.1"/>
      </material>
    </collision>
  </link>
  <!-- CAMERA -->
  <!--<joint name="upper_beam_to_realsense2" type="fixed">
    <parent link="table"/>
    <child link="realsense_holder1"/>
    <origin xyz="0.881438574717 0.787357038996 -0.685421164733" rpy="0.008 0.662 -1.725"/>
  </joint>

<link name="realsense_holder1"/>

<xacro:sensor_d435 parent="realsense_holder1" use_nominal_extrinsics="false">
  <origin xyz="0 0 0" rpy="0 0 0"/>
</xacro:sensor_d435>
-->
</robot>
